2019-03-04 22:45:41  django.server  INFO  [124]   "GET /dashboard/user/ HTTP/1.1" 200 480
2019-03-04 22:45:41  django.server  INFO  [124]   "GET /dashboard/user/ HTTP/1.1" 200 480
2019-03-05 21:02:34  django.server  INFO  [124]   "GET /dashboard/user/ HTTP/1.1" 200 480
2019-03-05 21:02:34  django.template  DEBUG  [925]   Exception while resolving variable 'name' in template 'unknown'.
Traceback (most recent call last):
  File "/Library/Frameworks/Python.framework/Versions/3.6/lib/python3.6/site-packages/django/core/handlers/exception.py", line 41, in inner
    response = get_response(request)
  File "/Library/Frameworks/Python.framework/Versions/3.6/lib/python3.6/site-packages/django/core/handlers/base.py", line 172, in _get_response
    resolver_match = resolver.resolve(request.path_info)
  File "/Library/Frameworks/Python.framework/Versions/3.6/lib/python3.6/site-packages/django/urls/resolvers.py", line 394, in resolve
    raise Resolver404({'tried': tried, 'path': new_path})
django.urls.exceptions.Resolver404: {'tried': [[<RegexURLResolver <RegexURLPattern list> (admin:admin) ^admin/>], [<RegexURLResolver <module 'dashboard.urls' from '/Users/yangyang/Documents/devops_study/ops/dashboard/urls.py'> (None:None) ^dashboard/>]], 'path': 'favicon.ico'}

During handling of the above exception, another exception occurred:

Traceback (most recent call last):
  File "/Library/Frameworks/Python.framework/Versions/3.6/lib/python3.6/site-packages/django/template/base.py", line 882, in _resolve_lookup
    current = current[bit]
TypeError: 'RegexURLResolver' object is not subscriptable

During handling of the above exception, another exception occurred:

Traceback (most recent call last):
  File "/Library/Frameworks/Python.framework/Versions/3.6/lib/python3.6/site-packages/django/template/base.py", line 890, in _resolve_lookup
    current = getattr(current, bit)
AttributeError: 'RegexURLResolver' object has no attribute 'name'

During handling of the above exception, another exception occurred:

Traceback (most recent call last):
  File "/Library/Frameworks/Python.framework/Versions/3.6/lib/python3.6/site-packages/django/template/base.py", line 896, in _resolve_lookup
    current = current[int(bit)]
ValueError: invalid literal for int() with base 10: 'name'

During handling of the above exception, another exception occurred:

Traceback (most recent call last):
  File "/Library/Frameworks/Python.framework/Versions/3.6/lib/python3.6/site-packages/django/template/base.py", line 903, in _resolve_lookup
    (bit, current))  # missing attribute
django.template.base.VariableDoesNotExist: Failed lookup for key [name] in '<RegexURLResolver <RegexURLPattern list> (admin:admin) ^admin/>'
2019-03-05 21:02:34  django.template  DEBUG  [925]   Exception while resolving variable 'name' in template 'unknown'.
Traceback (most recent call last):
  File "/Library/Frameworks/Python.framework/Versions/3.6/lib/python3.6/site-packages/django/core/handlers/exception.py", line 41, in inner
    response = get_response(request)
  File "/Library/Frameworks/Python.framework/Versions/3.6/lib/python3.6/site-packages/django/core/handlers/base.py", line 172, in _get_response
    resolver_match = resolver.resolve(request.path_info)
  File "/Library/Frameworks/Python.framework/Versions/3.6/lib/python3.6/site-packages/django/urls/resolvers.py", line 394, in resolve
    raise Resolver404({'tried': tried, 'path': new_path})
django.urls.exceptions.Resolver404: {'tried': [[<RegexURLResolver <RegexURLPattern list> (admin:admin) ^admin/>], [<RegexURLResolver <module 'dashboard.urls' from '/Users/yangyang/Documents/devops_study/ops/dashboard/urls.py'> (None:None) ^dashboard/>]], 'path': 'favicon.ico'}

During handling of the above exception, another exception occurred:

Traceback (most recent call last):
  File "/Library/Frameworks/Python.framework/Versions/3.6/lib/python3.6/site-packages/django/template/base.py", line 882, in _resolve_lookup
    current = current[bit]
TypeError: 'RegexURLResolver' object is not subscriptable

During handling of the above exception, another exception occurred:

Traceback (most recent call last):
  File "/Library/Frameworks/Python.framework/Versions/3.6/lib/python3.6/site-packages/django/template/base.py", line 890, in _resolve_lookup
    current = getattr(current, bit)
AttributeError: 'RegexURLResolver' object has no attribute 'name'

During handling of the above exception, another exception occurred:

Traceback (most recent call last):
  File "/Library/Frameworks/Python.framework/Versions/3.6/lib/python3.6/site-packages/django/template/base.py", line 896, in _resolve_lookup
    current = current[int(bit)]
ValueError: invalid literal for int() with base 10: 'name'

During handling of the above exception, another exception occurred:

Traceback (most recent call last):
  File "/Library/Frameworks/Python.framework/Versions/3.6/lib/python3.6/site-packages/django/template/base.py", line 903, in _resolve_lookup
    (bit, current))  # missing attribute
django.template.base.VariableDoesNotExist: Failed lookup for key [name] in "<RegexURLResolver <module 'dashboard.urls' from '/Users/yangyang/Documents/devops_study/ops/dashboard/urls.py'> (None:None) ^dashboard/>"
2019-03-05 21:02:34  django.request  WARNING  [152]   Not Found: /favicon.ico
2019-03-05 21:02:34  django.server  WARNING  [124]   "GET /favicon.ico HTTP/1.1" 404 2070
2019-03-05 21:29:19  django.template  DEBUG  [925]   Exception while resolving variable 'name' in template 'unknown'.
Traceback (most recent call last):
  File "/Library/Frameworks/Python.framework/Versions/3.6/lib/python3.6/site-packages/django/core/handlers/exception.py", line 41, in inner
    response = get_response(request)
  File "/Library/Frameworks/Python.framework/Versions/3.6/lib/python3.6/site-packages/django/core/handlers/base.py", line 172, in _get_response
    resolver_match = resolver.resolve(request.path_info)
  File "/Library/Frameworks/Python.framework/Versions/3.6/lib/python3.6/site-packages/django/urls/resolvers.py", line 394, in resolve
    raise Resolver404({'tried': tried, 'path': new_path})
django.urls.exceptions.Resolver404: {'tried': [[<RegexURLResolver <RegexURLPattern list> (admin:admin) ^admin/>], [<RegexURLResolver <module 'dashboard.urls' from '/Users/yangyang/Documents/devops_study/ops/dashboard/urls.py'> (None:None) ^dashboard/>, <RegexURLPattern hello hello/>]], 'path': 'dashboard/user/'}

During handling of the above exception, another exception occurred:

Traceback (most recent call last):
  File "/Library/Frameworks/Python.framework/Versions/3.6/lib/python3.6/site-packages/django/template/base.py", line 882, in _resolve_lookup
    current = current[bit]
TypeError: 'RegexURLResolver' object is not subscriptable

During handling of the above exception, another exception occurred:

Traceback (most recent call last):
  File "/Library/Frameworks/Python.framework/Versions/3.6/lib/python3.6/site-packages/django/template/base.py", line 890, in _resolve_lookup
    current = getattr(current, bit)
AttributeError: 'RegexURLResolver' object has no attribute 'name'

During handling of the above exception, another exception occurred:

Traceback (most recent call last):
  File "/Library/Frameworks/Python.framework/Versions/3.6/lib/python3.6/site-packages/django/template/base.py", line 896, in _resolve_lookup
    current = current[int(bit)]
ValueError: invalid literal for int() with base 10: 'name'

During handling of the above exception, another exception occurred:

Traceback (most recent call last):
  File "/Library/Frameworks/Python.framework/Versions/3.6/lib/python3.6/site-packages/django/template/base.py", line 903, in _resolve_lookup
    (bit, current))  # missing attribute
django.template.base.VariableDoesNotExist: Failed lookup for key [name] in '<RegexURLResolver <RegexURLPattern list> (admin:admin) ^admin/>'
2019-03-05 21:29:19  django.request  WARNING  [152]   Not Found: /dashboard/user/
2019-03-05 21:29:19  django.server  WARNING  [124]   "GET /dashboard/user/ HTTP/1.1" 404 2149
2019-03-05 21:29:27  django.server  INFO  [124]   "GET /dashboard/hello/ HTTP/1.1" 200 0
2019-03-05 21:32:10  django.request  ERROR  [135]   Internal Server Error: /dashboard/hello/
Traceback (most recent call last):
  File "/Library/Frameworks/Python.framework/Versions/3.6/lib/python3.6/site-packages/django/core/handlers/exception.py", line 41, in inner
    response = get_response(request)
  File "/Library/Frameworks/Python.framework/Versions/3.6/lib/python3.6/site-packages/django/core/handlers/base.py", line 187, in _get_response
    response = self.process_exception_by_middleware(e, request)
  File "/Library/Frameworks/Python.framework/Versions/3.6/lib/python3.6/site-packages/django/core/handlers/base.py", line 185, in _get_response
    response = wrapped_callback(request, *callback_args, **callback_kwargs)
  File "/Library/Frameworks/Python.framework/Versions/3.6/lib/python3.6/site-packages/django/views/generic/base.py", line 68, in view
    return self.dispatch(request, *args, **kwargs)
  File "/Library/Frameworks/Python.framework/Versions/3.6/lib/python3.6/site-packages/django/views/generic/base.py", line 88, in dispatch
    return handler(request, *args, **kwargs)
  File "/Users/yangyang/Documents/devops_study/ops/dashboard/views.py", line 95, in get
    return JsonResponse(queryset)
  File "/Library/Frameworks/Python.framework/Versions/3.6/lib/python3.6/site-packages/django/http/response.py", line 524, in __init__
    'In order to allow non-dict objects to be serialized set the '
TypeError: In order to allow non-dict objects to be serialized set the safe parameter to False.
2019-03-05 21:32:10  django.server  ERROR  [124]   "GET /dashboard/hello/ HTTP/1.1" 500 82220
2019-03-05 21:32:35  django.server  INFO  [124]   "GET /dashboard/hello/ HTTP/1.1" 200 761
2019-03-05 21:35:27  django.server  INFO  [124]   "GET /dashboard/hello/ HTTP/1.1" 200 761
2019-03-05 21:35:45  django.server  INFO  [124]   "GET /dashboard/hello/ HTTP/1.1" 200 761
2019-03-05 21:35:46  django.server  INFO  [124]   "GET /dashboard/hello/ HTTP/1.1" 200 761
2019-03-05 21:35:47  django.server  INFO  [124]   "GET /dashboard/hello/ HTTP/1.1" 200 761
2019-03-05 21:35:48  django.server  INFO  [124]   "GET /dashboard/hello/ HTTP/1.1" 200 761
2019-03-05 21:35:49  django.server  INFO  [124]   "GET /dashboard/hello/ HTTP/1.1" 200 761
2019-03-05 21:38:53  django.server  INFO  [124]   "GET /dashboard/hello/ HTTP/1.1" 200 761
2019-03-05 21:39:01  django.request  ERROR  [135]   Internal Server Error: /dashboard/hello/
Traceback (most recent call last):
  File "/Library/Frameworks/Python.framework/Versions/3.6/lib/python3.6/site-packages/django/core/handlers/exception.py", line 41, in inner
    response = get_response(request)
  File "/Library/Frameworks/Python.framework/Versions/3.6/lib/python3.6/site-packages/django/core/handlers/base.py", line 187, in _get_response
    response = self.process_exception_by_middleware(e, request)
  File "/Library/Frameworks/Python.framework/Versions/3.6/lib/python3.6/site-packages/django/core/handlers/base.py", line 185, in _get_response
    response = wrapped_callback(request, *callback_args, **callback_kwargs)
  File "/Library/Frameworks/Python.framework/Versions/3.6/lib/python3.6/site-packages/django/views/generic/base.py", line 68, in view
    return self.dispatch(request, *args, **kwargs)
  File "/Library/Frameworks/Python.framework/Versions/3.6/lib/python3.6/site-packages/django/views/generic/base.py", line 88, in dispatch
    return handler(request, *args, **kwargs)
  File "/Users/yangyang/Documents/devops_study/ops/dashboard/views.py", line 92, in get
    queryset = self.get_paginate_queryset(queryset)
  File "/Users/yangyang/Documents/devops_study/ops/dashboard/views.py", line 112, in get_paginate_queryset
    paginator = Paginator(queryset,self.get_per_page())
TypeError: get_per_page() missing 1 required positional argument: 'request'
2019-03-05 21:39:01  django.server  ERROR  [124]   "GET /dashboard/hello/?per_page=3 HTTP/1.1" 500 83736
2019-03-05 21:39:29  django.request  ERROR  [135]   Internal Server Error: /dashboard/hello/
Traceback (most recent call last):
  File "/Library/Frameworks/Python.framework/Versions/3.6/lib/python3.6/site-packages/django/core/paginator.py", line 41, in validate_number
    number = int(number)
TypeError: int() argument must be a string, a bytes-like object or a number, not 'NoneType'

During handling of the above exception, another exception occurred:

Traceback (most recent call last):
  File "/Library/Frameworks/Python.framework/Versions/3.6/lib/python3.6/site-packages/django/core/handlers/exception.py", line 41, in inner
    response = get_response(request)
  File "/Library/Frameworks/Python.framework/Versions/3.6/lib/python3.6/site-packages/django/core/handlers/base.py", line 187, in _get_response
    response = self.process_exception_by_middleware(e, request)
  File "/Library/Frameworks/Python.framework/Versions/3.6/lib/python3.6/site-packages/django/core/handlers/base.py", line 185, in _get_response
    response = wrapped_callback(request, *callback_args, **callback_kwargs)
  File "/Library/Frameworks/Python.framework/Versions/3.6/lib/python3.6/site-packages/django/views/generic/base.py", line 68, in view
    return self.dispatch(request, *args, **kwargs)
  File "/Library/Frameworks/Python.framework/Versions/3.6/lib/python3.6/site-packages/django/views/generic/base.py", line 88, in dispatch
    return handler(request, *args, **kwargs)
  File "/Users/yangyang/Documents/devops_study/ops/dashboard/views.py", line 92, in get
    queryset = self.get_paginate_queryset(queryset)
  File "/Users/yangyang/Documents/devops_study/ops/dashboard/views.py", line 113, in get_paginate_queryset
    page_obj = paginator.page(self.get_current_per_page())
  File "/Library/Frameworks/Python.framework/Versions/3.6/lib/python3.6/site-packages/django/core/paginator.py", line 57, in page
    number = self.validate_number(number)
  File "/Library/Frameworks/Python.framework/Versions/3.6/lib/python3.6/site-packages/django/core/paginator.py", line 43, in validate_number
    raise PageNotAnInteger(_('That page number is not an integer'))
django.core.paginator.PageNotAnInteger: That page number is not an integer
2019-03-05 21:39:29  django.server  ERROR  [124]   "GET /dashboard/hello/?per_page=3 HTTP/1.1" 500 95715
2019-03-05 21:39:31  django.request  ERROR  [135]   Internal Server Error: /dashboard/hello/
Traceback (most recent call last):
  File "/Library/Frameworks/Python.framework/Versions/3.6/lib/python3.6/site-packages/django/core/paginator.py", line 41, in validate_number
    number = int(number)
TypeError: int() argument must be a string, a bytes-like object or a number, not 'NoneType'

During handling of the above exception, another exception occurred:

Traceback (most recent call last):
  File "/Library/Frameworks/Python.framework/Versions/3.6/lib/python3.6/site-packages/django/core/handlers/exception.py", line 41, in inner
    response = get_response(request)
  File "/Library/Frameworks/Python.framework/Versions/3.6/lib/python3.6/site-packages/django/core/handlers/base.py", line 187, in _get_response
    response = self.process_exception_by_middleware(e, request)
  File "/Library/Frameworks/Python.framework/Versions/3.6/lib/python3.6/site-packages/django/core/handlers/base.py", line 185, in _get_response
    response = wrapped_callback(request, *callback_args, **callback_kwargs)
  File "/Library/Frameworks/Python.framework/Versions/3.6/lib/python3.6/site-packages/django/views/generic/base.py", line 68, in view
    return self.dispatch(request, *args, **kwargs)
  File "/Library/Frameworks/Python.framework/Versions/3.6/lib/python3.6/site-packages/django/views/generic/base.py", line 88, in dispatch
    return handler(request, *args, **kwargs)
  File "/Users/yangyang/Documents/devops_study/ops/dashboard/views.py", line 92, in get
    queryset = self.get_paginate_queryset(queryset)
  File "/Users/yangyang/Documents/devops_study/ops/dashboard/views.py", line 113, in get_paginate_queryset
    page_obj = paginator.page(self.get_current_per_page())
  File "/Library/Frameworks/Python.framework/Versions/3.6/lib/python3.6/site-packages/django/core/paginator.py", line 57, in page
    number = self.validate_number(number)
  File "/Library/Frameworks/Python.framework/Versions/3.6/lib/python3.6/site-packages/django/core/paginator.py", line 43, in validate_number
    raise PageNotAnInteger(_('That page number is not an integer'))
django.core.paginator.PageNotAnInteger: That page number is not an integer
2019-03-05 21:39:31  django.server  ERROR  [124]   "GET /dashboard/hello/?per_page=3 HTTP/1.1" 500 95716
2019-03-05 21:40:41  django.request  ERROR  [135]   Internal Server Error: /dashboard/hello/
Traceback (most recent call last):
  File "/Library/Frameworks/Python.framework/Versions/3.6/lib/python3.6/site-packages/django/core/paginator.py", line 41, in validate_number
    number = int(number)
TypeError: int() argument must be a string, a bytes-like object or a number, not 'NoneType'

During handling of the above exception, another exception occurred:

Traceback (most recent call last):
  File "/Library/Frameworks/Python.framework/Versions/3.6/lib/python3.6/site-packages/django/core/handlers/exception.py", line 41, in inner
    response = get_response(request)
  File "/Library/Frameworks/Python.framework/Versions/3.6/lib/python3.6/site-packages/django/core/handlers/base.py", line 187, in _get_response
    response = self.process_exception_by_middleware(e, request)
  File "/Library/Frameworks/Python.framework/Versions/3.6/lib/python3.6/site-packages/django/core/handlers/base.py", line 185, in _get_response
    response = wrapped_callback(request, *callback_args, **callback_kwargs)
  File "/Library/Frameworks/Python.framework/Versions/3.6/lib/python3.6/site-packages/django/views/generic/base.py", line 68, in view
    return self.dispatch(request, *args, **kwargs)
  File "/Library/Frameworks/Python.framework/Versions/3.6/lib/python3.6/site-packages/django/views/generic/base.py", line 88, in dispatch
    return handler(request, *args, **kwargs)
  File "/Users/yangyang/Documents/devops_study/ops/dashboard/views.py", line 92, in get
    queryset = self.get_paginate_queryset(queryset)
  File "/Users/yangyang/Documents/devops_study/ops/dashboard/views.py", line 113, in get_paginate_queryset
    page_obj = paginator.page(self.get_current_per_page())
  File "/Library/Frameworks/Python.framework/Versions/3.6/lib/python3.6/site-packages/django/core/paginator.py", line 57, in page
    number = self.validate_number(number)
  File "/Library/Frameworks/Python.framework/Versions/3.6/lib/python3.6/site-packages/django/core/paginator.py", line 43, in validate_number
    raise PageNotAnInteger(_('That page number is not an integer'))
django.core.paginator.PageNotAnInteger: That page number is not an integer
2019-03-05 21:40:41  django.server  ERROR  [124]   "GET /dashboard/hello/?per_page=3 HTTP/1.1" 500 95715
2019-03-05 21:41:27  django.server  INFO  [124]   "GET /dashboard/hello/?per_page=3 HTTP/1.1" 200 228
2019-03-05 21:41:39  django.server  INFO  [124]   "GET /dashboard/hello/?per_page=3&page=100 HTTP/1.1" 200 240
2019-03-05 21:44:55  django.server  INFO  [124]   "GET /dashboard/hello/?per_page=3&page=100 HTTP/1.1" 200 240
