2019-03-05 21:02:34  django.request  WARNING  [152]   Not Found: /favicon.ico
2019-03-05 21:29:19  django.request  WARNING  [152]   Not Found: /dashboard/user/
2019-03-05 21:32:10  django.request  ERROR  [135]   Internal Server Error: /dashboard/hello/
Traceback (most recent call last):
  File "/Library/Frameworks/Python.framework/Versions/3.6/lib/python3.6/site-packages/django/core/handlers/exception.py", line 41, in inner
    response = get_response(request)
  File "/Library/Frameworks/Python.framework/Versions/3.6/lib/python3.6/site-packages/django/core/handlers/base.py", line 187, in _get_response
    response = self.process_exception_by_middleware(e, request)
  File "/Library/Frameworks/Python.framework/Versions/3.6/lib/python3.6/site-packages/django/core/handlers/base.py", line 185, in _get_response
    response = wrapped_callback(request, *callback_args, **callback_kwargs)
  File "/Library/Frameworks/Python.framework/Versions/3.6/lib/python3.6/site-packages/django/views/generic/base.py", line 68, in view
    return self.dispatch(request, *args, **kwargs)
  File "/Library/Frameworks/Python.framework/Versions/3.6/lib/python3.6/site-packages/django/views/generic/base.py", line 88, in dispatch
    return handler(request, *args, **kwargs)
  File "/Users/yangyang/Documents/devops_study/ops/dashboard/views.py", line 95, in get
    return JsonResponse(queryset)
  File "/Library/Frameworks/Python.framework/Versions/3.6/lib/python3.6/site-packages/django/http/response.py", line 524, in __init__
    'In order to allow non-dict objects to be serialized set the '
TypeError: In order to allow non-dict objects to be serialized set the safe parameter to False.
2019-03-05 21:39:01  django.request  ERROR  [135]   Internal Server Error: /dashboard/hello/
Traceback (most recent call last):
  File "/Library/Frameworks/Python.framework/Versions/3.6/lib/python3.6/site-packages/django/core/handlers/exception.py", line 41, in inner
    response = get_response(request)
  File "/Library/Frameworks/Python.framework/Versions/3.6/lib/python3.6/site-packages/django/core/handlers/base.py", line 187, in _get_response
    response = self.process_exception_by_middleware(e, request)
  File "/Library/Frameworks/Python.framework/Versions/3.6/lib/python3.6/site-packages/django/core/handlers/base.py", line 185, in _get_response
    response = wrapped_callback(request, *callback_args, **callback_kwargs)
  File "/Library/Frameworks/Python.framework/Versions/3.6/lib/python3.6/site-packages/django/views/generic/base.py", line 68, in view
    return self.dispatch(request, *args, **kwargs)
  File "/Library/Frameworks/Python.framework/Versions/3.6/lib/python3.6/site-packages/django/views/generic/base.py", line 88, in dispatch
    return handler(request, *args, **kwargs)
  File "/Users/yangyang/Documents/devops_study/ops/dashboard/views.py", line 92, in get
    queryset = self.get_paginate_queryset(queryset)
  File "/Users/yangyang/Documents/devops_study/ops/dashboard/views.py", line 112, in get_paginate_queryset
    paginator = Paginator(queryset,self.get_per_page())
TypeError: get_per_page() missing 1 required positional argument: 'request'
2019-03-05 21:39:29  django.request  ERROR  [135]   Internal Server Error: /dashboard/hello/
Traceback (most recent call last):
  File "/Library/Frameworks/Python.framework/Versions/3.6/lib/python3.6/site-packages/django/core/paginator.py", line 41, in validate_number
    number = int(number)
TypeError: int() argument must be a string, a bytes-like object or a number, not 'NoneType'

During handling of the above exception, another exception occurred:

Traceback (most recent call last):
  File "/Library/Frameworks/Python.framework/Versions/3.6/lib/python3.6/site-packages/django/core/handlers/exception.py", line 41, in inner
    response = get_response(request)
  File "/Library/Frameworks/Python.framework/Versions/3.6/lib/python3.6/site-packages/django/core/handlers/base.py", line 187, in _get_response
    response = self.process_exception_by_middleware(e, request)
  File "/Library/Frameworks/Python.framework/Versions/3.6/lib/python3.6/site-packages/django/core/handlers/base.py", line 185, in _get_response
    response = wrapped_callback(request, *callback_args, **callback_kwargs)
  File "/Library/Frameworks/Python.framework/Versions/3.6/lib/python3.6/site-packages/django/views/generic/base.py", line 68, in view
    return self.dispatch(request, *args, **kwargs)
  File "/Library/Frameworks/Python.framework/Versions/3.6/lib/python3.6/site-packages/django/views/generic/base.py", line 88, in dispatch
    return handler(request, *args, **kwargs)
  File "/Users/yangyang/Documents/devops_study/ops/dashboard/views.py", line 92, in get
    queryset = self.get_paginate_queryset(queryset)
  File "/Users/yangyang/Documents/devops_study/ops/dashboard/views.py", line 113, in get_paginate_queryset
    page_obj = paginator.page(self.get_current_per_page())
  File "/Library/Frameworks/Python.framework/Versions/3.6/lib/python3.6/site-packages/django/core/paginator.py", line 57, in page
    number = self.validate_number(number)
  File "/Library/Frameworks/Python.framework/Versions/3.6/lib/python3.6/site-packages/django/core/paginator.py", line 43, in validate_number
    raise PageNotAnInteger(_('That page number is not an integer'))
django.core.paginator.PageNotAnInteger: That page number is not an integer
2019-03-05 21:39:31  django.request  ERROR  [135]   Internal Server Error: /dashboard/hello/
Traceback (most recent call last):
  File "/Library/Frameworks/Python.framework/Versions/3.6/lib/python3.6/site-packages/django/core/paginator.py", line 41, in validate_number
    number = int(number)
TypeError: int() argument must be a string, a bytes-like object or a number, not 'NoneType'

During handling of the above exception, another exception occurred:

Traceback (most recent call last):
  File "/Library/Frameworks/Python.framework/Versions/3.6/lib/python3.6/site-packages/django/core/handlers/exception.py", line 41, in inner
    response = get_response(request)
  File "/Library/Frameworks/Python.framework/Versions/3.6/lib/python3.6/site-packages/django/core/handlers/base.py", line 187, in _get_response
    response = self.process_exception_by_middleware(e, request)
  File "/Library/Frameworks/Python.framework/Versions/3.6/lib/python3.6/site-packages/django/core/handlers/base.py", line 185, in _get_response
    response = wrapped_callback(request, *callback_args, **callback_kwargs)
  File "/Library/Frameworks/Python.framework/Versions/3.6/lib/python3.6/site-packages/django/views/generic/base.py", line 68, in view
    return self.dispatch(request, *args, **kwargs)
  File "/Library/Frameworks/Python.framework/Versions/3.6/lib/python3.6/site-packages/django/views/generic/base.py", line 88, in dispatch
    return handler(request, *args, **kwargs)
  File "/Users/yangyang/Documents/devops_study/ops/dashboard/views.py", line 92, in get
    queryset = self.get_paginate_queryset(queryset)
  File "/Users/yangyang/Documents/devops_study/ops/dashboard/views.py", line 113, in get_paginate_queryset
    page_obj = paginator.page(self.get_current_per_page())
  File "/Library/Frameworks/Python.framework/Versions/3.6/lib/python3.6/site-packages/django/core/paginator.py", line 57, in page
    number = self.validate_number(number)
  File "/Library/Frameworks/Python.framework/Versions/3.6/lib/python3.6/site-packages/django/core/paginator.py", line 43, in validate_number
    raise PageNotAnInteger(_('That page number is not an integer'))
django.core.paginator.PageNotAnInteger: That page number is not an integer
2019-03-05 21:40:41  django.request  ERROR  [135]   Internal Server Error: /dashboard/hello/
Traceback (most recent call last):
  File "/Library/Frameworks/Python.framework/Versions/3.6/lib/python3.6/site-packages/django/core/paginator.py", line 41, in validate_number
    number = int(number)
TypeError: int() argument must be a string, a bytes-like object or a number, not 'NoneType'

During handling of the above exception, another exception occurred:

Traceback (most recent call last):
  File "/Library/Frameworks/Python.framework/Versions/3.6/lib/python3.6/site-packages/django/core/handlers/exception.py", line 41, in inner
    response = get_response(request)
  File "/Library/Frameworks/Python.framework/Versions/3.6/lib/python3.6/site-packages/django/core/handlers/base.py", line 187, in _get_response
    response = self.process_exception_by_middleware(e, request)
  File "/Library/Frameworks/Python.framework/Versions/3.6/lib/python3.6/site-packages/django/core/handlers/base.py", line 185, in _get_response
    response = wrapped_callback(request, *callback_args, **callback_kwargs)
  File "/Library/Frameworks/Python.framework/Versions/3.6/lib/python3.6/site-packages/django/views/generic/base.py", line 68, in view
    return self.dispatch(request, *args, **kwargs)
  File "/Library/Frameworks/Python.framework/Versions/3.6/lib/python3.6/site-packages/django/views/generic/base.py", line 88, in dispatch
    return handler(request, *args, **kwargs)
  File "/Users/yangyang/Documents/devops_study/ops/dashboard/views.py", line 92, in get
    queryset = self.get_paginate_queryset(queryset)
  File "/Users/yangyang/Documents/devops_study/ops/dashboard/views.py", line 113, in get_paginate_queryset
    page_obj = paginator.page(self.get_current_per_page())
  File "/Library/Frameworks/Python.framework/Versions/3.6/lib/python3.6/site-packages/django/core/paginator.py", line 57, in page
    number = self.validate_number(number)
  File "/Library/Frameworks/Python.framework/Versions/3.6/lib/python3.6/site-packages/django/core/paginator.py", line 43, in validate_number
    raise PageNotAnInteger(_('That page number is not an integer'))
django.core.paginator.PageNotAnInteger: That page number is not an integer
