<<<<<<< HEAD
2019-03-06 17:45:32  django.request  WARNING  [152]   Not Found: /
2019-03-06 17:48:07  django.request  WARNING  [152]   Not Found: /login/
2019-03-07 13:05:11  django.request  ERROR  [135]   Internal Server Error: /idcs/
Traceback (most recent call last):
  File "C:\Python\Python36\lib\site-packages\django\core\handlers\exception.py", line 41, in inner
    response = get_response(request)
  File "C:\Python\Python36\lib\site-packages\django\core\handlers\base.py", line 187, in _get_response
    response = self.process_exception_by_middleware(e, request)
  File "C:\Python\Python36\lib\site-packages\django\core\handlers\base.py", line 185, in _get_response
    response = wrapped_callback(request, *callback_args, **callback_kwargs)
  File "C:\Python\Python36\lib\site-packages\django\views\decorators\csrf.py", line 58, in wrapped_view
    return view_func(*args, **kwargs)
  File "C:\Python\Python36\lib\site-packages\django\views\generic\base.py", line 68, in view
    return self.dispatch(request, *args, **kwargs)
  File "C:\Python\Python36\lib\site-packages\rest_framework\views.py", line 495, in dispatch
    response = self.handle_exception(exc)
  File "C:\Python\Python36\lib\site-packages\rest_framework\views.py", line 455, in handle_exception
    self.raise_uncaught_exception(exc)
  File "C:\Python\Python36\lib\site-packages\rest_framework\views.py", line 492, in dispatch
    response = handler(request, *args, **kwargs)
  File "C:\Python\Python36\lib\site-packages\rest_framework\decorators.py", line 55, in handler
    return func(*args, **kwargs)
  File "D:\gitcode\devops_study\ops\apps\idcs\views.py", line 75, in idc_list_v2
    return JSONResponse(status=status.HTTP_400_BAD_REQUEST)
TypeError: __init__() missing 1 required positional argument: 'data'
2019-03-07 13:15:07  django.request  WARNING  [152]   Not Found: /idcs/2/
2019-03-07 13:16:45  django.request  WARNING  [152]   Not Found: /idcs/2/
2019-03-07 13:22:56  django.request  WARNING  [152]   Not Found: /dashboard/user/
2019-03-07 13:31:26  django.request  WARNING  [152]   Not Found: /idcs/2.api
2019-03-07 13:32:28  django.request  WARNING  [152]   Not Found: /idcs.xml
2019-03-07 13:34:38  django.request  WARNING  [152]   Not Found: /idcs.xml
2019-03-07 13:36:55  django.request  WARNING  [152]   Not Found: /idcs/1.api
2019-03-07 13:37:10  django.request  WARNING  [152]   Not Found: /idc_detail_v2/
2019-03-07 13:37:49  django.request  WARNING  [152]   Not Found: /idcs/2.json
2019-03-07 13:38:04  django.request  WARNING  [152]   Not Found: /idcs/2.json
2019-03-07 13:38:18  django.request  WARNING  [152]   Not Found: /idcs/2.api
2019-03-07 13:38:53  django.request  WARNING  [152]   Not Found: /idcs/2.api
2019-03-07 13:38:55  django.request  WARNING  [152]   Not Found: /idcs/2.api
2019-03-07 13:39:25  django.request  WARNING  [152]   Not Found: /idcs/2.api
2019-03-07 13:39:27  django.request  WARNING  [152]   Not Found: /idcs/2.api
2019-03-07 13:39:30  django.request  WARNING  [152]   Not Found: /idcs/2
2019-03-07 13:40:31  django.request  WARNING  [152]   Not Found: /idcs/2.json
2019-03-07 13:40:56  django.request  WARNING  [152]   Not Found: /idcs/2
2019-03-07 15:19:04  django.request  ERROR  [135]   Internal Server Error: /
Traceback (most recent call last):
  File "C:\Python\Python36\lib\site-packages\django\core\handlers\exception.py", line 41, in inner
    response = get_response(request)
  File "C:\Python\Python36\lib\site-packages\django\core\handlers\base.py", line 187, in _get_response
    response = self.process_exception_by_middleware(e, request)
  File "C:\Python\Python36\lib\site-packages\django\core\handlers\base.py", line 185, in _get_response
    response = wrapped_callback(request, *callback_args, **callback_kwargs)
  File "C:\Python\Python36\lib\site-packages\django\views\decorators\csrf.py", line 58, in wrapped_view
    return view_func(*args, **kwargs)
  File "C:\Python\Python36\lib\site-packages\django\views\generic\base.py", line 68, in view
    return self.dispatch(request, *args, **kwargs)
  File "C:\Python\Python36\lib\site-packages\rest_framework\views.py", line 495, in dispatch
    response = self.handle_exception(exc)
  File "C:\Python\Python36\lib\site-packages\rest_framework\views.py", line 455, in handle_exception
    self.raise_uncaught_exception(exc)
  File "C:\Python\Python36\lib\site-packages\rest_framework\views.py", line 492, in dispatch
    response = handler(request, *args, **kwargs)
  File "C:\Python\Python36\lib\site-packages\rest_framework\decorators.py", line 55, in handler
    return func(*args, **kwargs)
  File "D:\gitcode\devops_study\ops\apps\idcs\views.py", line 106, in api_root
    "idcs":reverse("idc_list_v2",request=request,format=format)
  File "C:\Python\Python36\lib\site-packages\rest_framework\reverse.py", line 50, in reverse
    url = _reverse(viewname, args, kwargs, request, format, **extra)
  File "C:\Python\Python36\lib\site-packages\rest_framework\reverse.py", line 63, in _reverse
    url = django_reverse(viewname, args=args, kwargs=kwargs, **extra)
  File "C:\Python\Python36\lib\site-packages\django\urls\base.py", line 91, in reverse
    return force_text(iri_to_uri(resolver._reverse_with_prefix(view, prefix, *args, **kwargs)))
  File "C:\Python\Python36\lib\site-packages\django\urls\resolvers.py", line 497, in _reverse_with_prefix
    raise NoReverseMatch(msg)
django.urls.exceptions.NoReverseMatch: Reverse for 'idc_list_v2' not found. 'idc_list_v2' is not a valid view function or pattern name.
2019-03-07 15:19:34  django.request  WARNING  [152]   Not Found: /idcs/3/
2019-03-07 16:45:55  django.request  WARNING  [152]   Not Found: /login/
2019-03-07 16:47:17  django.request  WARNING  [152]   Not Found: /idcs/4
2019-03-07 17:17:22  django.request  ERROR  [135]   Internal Server Error: /idcs/
Traceback (most recent call last):
  File "C:\Python\Python36\lib\site-packages\django\core\handlers\exception.py", line 41, in inner
    response = get_response(request)
  File "C:\Python\Python36\lib\site-packages\django\core\handlers\base.py", line 187, in _get_response
    response = self.process_exception_by_middleware(e, request)
  File "C:\Python\Python36\lib\site-packages\django\core\handlers\base.py", line 185, in _get_response
    response = wrapped_callback(request, *callback_args, **callback_kwargs)
  File "C:\Python\Python36\lib\site-packages\django\views\decorators\csrf.py", line 58, in wrapped_view
    return view_func(*args, **kwargs)
  File "C:\Python\Python36\lib\site-packages\rest_framework\viewsets.py", line 116, in view
    return self.dispatch(request, *args, **kwargs)
  File "C:\Python\Python36\lib\site-packages\rest_framework\views.py", line 495, in dispatch
    response = self.handle_exception(exc)
  File "C:\Python\Python36\lib\site-packages\rest_framework\views.py", line 455, in handle_exception
    self.raise_uncaught_exception(exc)
  File "C:\Python\Python36\lib\site-packages\rest_framework\views.py", line 492, in dispatch
    response = handler(request, *args, **kwargs)
  File "C:\Python\Python36\lib\site-packages\rest_framework\mixins.py", line 40, in list
    queryset = self.filter_queryset(self.get_queryset())
AttributeError: 'IdcListViewSet' object has no attribute 'filter_queryset'
2019-03-07 17:29:20  django.request  ERROR  [135]   Internal Server Error: /idcs/5/
Traceback (most recent call last):
  File "C:\Python\Python36\lib\site-packages\django\core\handlers\exception.py", line 41, in inner
    response = get_response(request)
  File "C:\Python\Python36\lib\site-packages\django\core\handlers\base.py", line 187, in _get_response
    response = self.process_exception_by_middleware(e, request)
  File "C:\Python\Python36\lib\site-packages\django\core\handlers\base.py", line 185, in _get_response
    response = wrapped_callback(request, *callback_args, **callback_kwargs)
  File "C:\Python\Python36\lib\site-packages\django\views\decorators\csrf.py", line 58, in wrapped_view
    return view_func(*args, **kwargs)
  File "C:\Python\Python36\lib\site-packages\rest_framework\viewsets.py", line 105, in view
    handler = getattr(self, action)
AttributeError: 'IdcListViewSet' object has no attribute 'update'
2019-03-07 17:29:41  django.request  ERROR  [135]   Internal Server Error: /idcs/5/
Traceback (most recent call last):
  File "C:\Python\Python36\lib\site-packages\django\core\handlers\exception.py", line 41, in inner
    response = get_response(request)
  File "C:\Python\Python36\lib\site-packages\django\core\handlers\base.py", line 187, in _get_response
    response = self.process_exception_by_middleware(e, request)
  File "C:\Python\Python36\lib\site-packages\django\core\handlers\base.py", line 185, in _get_response
    response = wrapped_callback(request, *callback_args, **callback_kwargs)
  File "C:\Python\Python36\lib\site-packages\django\views\decorators\csrf.py", line 58, in wrapped_view
    return view_func(*args, **kwargs)
  File "C:\Python\Python36\lib\site-packages\rest_framework\viewsets.py", line 105, in view
    handler = getattr(self, action)
AttributeError: 'IdcListViewSet' object has no attribute 'destroy'
2019-03-07 17:29:48  django.request  ERROR  [135]   Internal Server Error: /idcs/
Traceback (most recent call last):
  File "C:\Python\Python36\lib\site-packages\django\core\handlers\exception.py", line 41, in inner
    response = get_response(request)
  File "C:\Python\Python36\lib\site-packages\django\core\handlers\base.py", line 187, in _get_response
    response = self.process_exception_by_middleware(e, request)
  File "C:\Python\Python36\lib\site-packages\django\core\handlers\base.py", line 185, in _get_response
    response = wrapped_callback(request, *callback_args, **callback_kwargs)
  File "C:\Python\Python36\lib\site-packages\django\views\decorators\csrf.py", line 58, in wrapped_view
    return view_func(*args, **kwargs)
  File "C:\Python\Python36\lib\site-packages\rest_framework\viewsets.py", line 105, in view
    handler = getattr(self, action)
AttributeError: 'IdcListViewSet' object has no attribute 'create'
2019-03-07 17:29:55  django.request  ERROR  [135]   Internal Server Error: /idcs/
Traceback (most recent call last):
  File "C:\Python\Python36\lib\site-packages\django\core\handlers\exception.py", line 41, in inner
    response = get_response(request)
  File "C:\Python\Python36\lib\site-packages\django\core\handlers\base.py", line 187, in _get_response
    response = self.process_exception_by_middleware(e, request)
  File "C:\Python\Python36\lib\site-packages\django\core\handlers\base.py", line 185, in _get_response
    response = wrapped_callback(request, *callback_args, **callback_kwargs)
  File "C:\Python\Python36\lib\site-packages\django\views\decorators\csrf.py", line 58, in wrapped_view
    return view_func(*args, **kwargs)
  File "C:\Python\Python36\lib\site-packages\rest_framework\viewsets.py", line 105, in view
    handler = getattr(self, action)
AttributeError: 'IdcListViewSet' object has no attribute 'create'
2019-03-07 17:48:19  django.request  WARNING  [152]   Not Found: /stark/asset/employee/list/
2019-03-07 19:12:40  django.request  WARNING  [152]   Not Found: /user/
2019-03-07 19:12:57  django.request  WARNING  [152]   Not Found: /users/login/
2019-03-07 19:13:11  django.request  WARNING  [152]   Not Found: /idcc
=======
2019-03-06 22:49:33  django.request  WARNING  [152]   Not Found: /stark/asset/fixphone/list
2019-03-06 22:50:02  django.request  WARNING  [152]   Not Found: /favicon.ico
2019-03-06 22:56:11  django.request  ERROR  [135]   Internal Server Error: /idcs/
Traceback (most recent call last):
  File "/Library/Frameworks/Python.framework/Versions/3.6/lib/python3.6/site-packages/django/core/handlers/exception.py", line 41, in inner
    response = get_response(request)
  File "/Library/Frameworks/Python.framework/Versions/3.6/lib/python3.6/site-packages/django/core/handlers/base.py", line 187, in _get_response
    response = self.process_exception_by_middleware(e, request)
  File "/Library/Frameworks/Python.framework/Versions/3.6/lib/python3.6/site-packages/django/core/handlers/base.py", line 185, in _get_response
    response = wrapped_callback(request, *callback_args, **callback_kwargs)
  File "/Users/yangyang/Documents/devops_study/ops/apps/idcs/views.py", line 20, in idc_list
    data = JSONParser.parse(request)
TypeError: parse() missing 1 required positional argument: 'stream'
2019-03-06 23:03:29  django.request  ERROR  [135]   Internal Server Error: /idcs
Traceback (most recent call last):
  File "/Library/Frameworks/Python.framework/Versions/3.6/lib/python3.6/site-packages/django/core/handlers/exception.py", line 41, in inner
    response = get_response(request)
  File "/Library/Frameworks/Python.framework/Versions/3.6/lib/python3.6/site-packages/django/utils/deprecation.py", line 138, in __call__
    response = self.process_request(request)
  File "/Library/Frameworks/Python.framework/Versions/3.6/lib/python3.6/site-packages/django/middleware/common.py", line 64, in process_request
    path = self.get_full_path_with_slash(request)
  File "/Library/Frameworks/Python.framework/Versions/3.6/lib/python3.6/site-packages/django/middleware/common.py", line 104, in get_full_path_with_slash
    'url': request.get_host() + new_path,
RuntimeError: You called this URL via POST, but the URL doesn't end in a slash and you have APPEND_SLASH set. Django can't redirect to the slash URL while maintaining POST data. Change your form to point to 127.0.0.1:8000/idcs/ (note the trailing slash), or set APPEND_SLASH=False in your Django settings.
2019-03-06 23:03:51  django.request  ERROR  [135]   Internal Server Error: /idcs
Traceback (most recent call last):
  File "/Library/Frameworks/Python.framework/Versions/3.6/lib/python3.6/site-packages/django/core/handlers/exception.py", line 41, in inner
    response = get_response(request)
  File "/Library/Frameworks/Python.framework/Versions/3.6/lib/python3.6/site-packages/django/utils/deprecation.py", line 138, in __call__
    response = self.process_request(request)
  File "/Library/Frameworks/Python.framework/Versions/3.6/lib/python3.6/site-packages/django/middleware/common.py", line 64, in process_request
    path = self.get_full_path_with_slash(request)
  File "/Library/Frameworks/Python.framework/Versions/3.6/lib/python3.6/site-packages/django/middleware/common.py", line 104, in get_full_path_with_slash
    'url': request.get_host() + new_path,
RuntimeError: You called this URL via POST, but the URL doesn't end in a slash and you have APPEND_SLASH set. Django can't redirect to the slash URL while maintaining POST data. Change your form to point to 127.0.0.1:8000/idcs/ (note the trailing slash), or set APPEND_SLASH=False in your Django settings.
2019-03-06 23:04:19  django.request  ERROR  [135]   Internal Server Error: /idcs/
Traceback (most recent call last):
  File "/Library/Frameworks/Python.framework/Versions/3.6/lib/python3.6/site-packages/django/core/handlers/exception.py", line 41, in inner
    response = get_response(request)
  File "/Library/Frameworks/Python.framework/Versions/3.6/lib/python3.6/site-packages/django/core/handlers/base.py", line 187, in _get_response
    response = self.process_exception_by_middleware(e, request)
  File "/Library/Frameworks/Python.framework/Versions/3.6/lib/python3.6/site-packages/django/core/handlers/base.py", line 185, in _get_response
    response = wrapped_callback(request, *callback_args, **callback_kwargs)
  File "/Users/yangyang/Documents/devops_study/ops/apps/idcs/views.py", line 20, in idc_list
    data = JSONParser.parse(request)
TypeError: parse() missing 1 required positional argument: 'stream'
2019-03-06 23:07:38  django.request  ERROR  [135]   Internal Server Error: /idcs/
Traceback (most recent call last):
  File "/Library/Frameworks/Python.framework/Versions/3.6/lib/python3.6/site-packages/django/core/handlers/exception.py", line 41, in inner
    response = get_response(request)
  File "/Library/Frameworks/Python.framework/Versions/3.6/lib/python3.6/site-packages/django/core/handlers/base.py", line 187, in _get_response
    response = self.process_exception_by_middleware(e, request)
  File "/Library/Frameworks/Python.framework/Versions/3.6/lib/python3.6/site-packages/django/core/handlers/base.py", line 185, in _get_response
    response = wrapped_callback(request, *callback_args, **callback_kwargs)
  File "/Users/yangyang/Documents/devops_study/ops/apps/idcs/views.py", line 20, in idc_list
    data = JSONParser.parse(request)
TypeError: parse() missing 1 required positional argument: 'stream'
2019-03-06 23:08:29  django.request  ERROR  [135]   Internal Server Error: /idcs/
Traceback (most recent call last):
  File "/Library/Frameworks/Python.framework/Versions/3.6/lib/python3.6/site-packages/django/core/handlers/exception.py", line 41, in inner
    response = get_response(request)
  File "/Library/Frameworks/Python.framework/Versions/3.6/lib/python3.6/site-packages/django/core/handlers/base.py", line 187, in _get_response
    response = self.process_exception_by_middleware(e, request)
  File "/Library/Frameworks/Python.framework/Versions/3.6/lib/python3.6/site-packages/django/core/handlers/base.py", line 185, in _get_response
    response = wrapped_callback(request, *callback_args, **callback_kwargs)
  File "/Users/yangyang/Documents/devops_study/ops/apps/idcs/views.py", line 20, in idc_list
    data = JSONParser.parse(request)
TypeError: parse() missing 1 required positional argument: 'stream'
2019-03-06 23:26:25  django.request  ERROR  [135]   Internal Server Error: /idcs/
Traceback (most recent call last):
  File "/Library/Frameworks/Python.framework/Versions/3.6/lib/python3.6/site-packages/django/core/handlers/exception.py", line 41, in inner
    response = get_response(request)
  File "/Library/Frameworks/Python.framework/Versions/3.6/lib/python3.6/site-packages/django/core/handlers/base.py", line 187, in _get_response
    response = self.process_exception_by_middleware(e, request)
  File "/Library/Frameworks/Python.framework/Versions/3.6/lib/python3.6/site-packages/django/core/handlers/base.py", line 185, in _get_response
    response = wrapped_callback(request, *callback_args, **callback_kwargs)
  File "/Users/yangyang/Documents/devops_study/ops/apps/idcs/views.py", line 25, in idc_list
    return  JSONResponse(serializer.data)
  File "/Users/yangyang/Documents/devops_study/ops/apps/idcs/views.py", line 16, in __init__
    super(JSONRenderer,self).__init__(data=content, **kwargs)
TypeError: super(type, obj): obj must be an instance or subtype of type
2019-03-06 23:26:41  django.request  ERROR  [135]   Internal Server Error: /idcs/
Traceback (most recent call last):
  File "/Library/Frameworks/Python.framework/Versions/3.6/lib/python3.6/site-packages/django/core/handlers/exception.py", line 41, in inner
    response = get_response(request)
  File "/Library/Frameworks/Python.framework/Versions/3.6/lib/python3.6/site-packages/django/core/handlers/base.py", line 187, in _get_response
    response = self.process_exception_by_middleware(e, request)
  File "/Library/Frameworks/Python.framework/Versions/3.6/lib/python3.6/site-packages/django/core/handlers/base.py", line 185, in _get_response
    response = wrapped_callback(request, *callback_args, **callback_kwargs)
  File "/Users/yangyang/Documents/devops_study/ops/apps/idcs/views.py", line 25, in idc_list
    return  JSONResponse(serializer.data)
  File "/Users/yangyang/Documents/devops_study/ops/apps/idcs/views.py", line 16, in __init__
    super(JSONRenderer,self).__init__(content=content, **kwargs)
TypeError: super(type, obj): obj must be an instance or subtype of type
2019-03-06 23:29:04  django.request  ERROR  [135]   Internal Server Error: /idcs/
Traceback (most recent call last):
  File "/Library/Frameworks/Python.framework/Versions/3.6/lib/python3.6/site-packages/django/core/handlers/exception.py", line 41, in inner
    response = get_response(request)
  File "/Library/Frameworks/Python.framework/Versions/3.6/lib/python3.6/site-packages/django/core/handlers/base.py", line 187, in _get_response
    response = self.process_exception_by_middleware(e, request)
  File "/Library/Frameworks/Python.framework/Versions/3.6/lib/python3.6/site-packages/django/core/handlers/base.py", line 185, in _get_response
    response = wrapped_callback(request, *callback_args, **callback_kwargs)
  File "/Users/yangyang/Documents/devops_study/ops/apps/idcs/views.py", line 25, in idc_list
    return  JSONResponse(serializer.data)
  File "/Users/yangyang/Documents/devops_study/ops/apps/idcs/views.py", line 16, in __init__
    super(JSONRenderer,self).__init__(content=content, **kwargs)
TypeError: super(type, obj): obj must be an instance or subtype of type
2019-03-06 23:47:41  django.request  ERROR  [135]   Internal Server Error: /idcs/1/
Traceback (most recent call last):
  File "/Library/Frameworks/Python.framework/Versions/3.6/lib/python3.6/site-packages/rest_framework/fields.py", line 453, in get_attribute
    return get_attribute(instance, self.source_attrs)
  File "/Library/Frameworks/Python.framework/Versions/3.6/lib/python3.6/site-packages/rest_framework/fields.py", line 101, in get_attribute
    instance = getattr(instance, attr)
AttributeError: 'QuerySet' object has no attribute 'name'

During handling of the above exception, another exception occurred:

Traceback (most recent call last):
  File "/Library/Frameworks/Python.framework/Versions/3.6/lib/python3.6/site-packages/django/core/handlers/exception.py", line 41, in inner
    response = get_response(request)
  File "/Library/Frameworks/Python.framework/Versions/3.6/lib/python3.6/site-packages/django/core/handlers/base.py", line 187, in _get_response
    response = self.process_exception_by_middleware(e, request)
  File "/Library/Frameworks/Python.framework/Versions/3.6/lib/python3.6/site-packages/django/core/handlers/base.py", line 185, in _get_response
    response = wrapped_callback(request, *callback_args, **callback_kwargs)
  File "/Users/yangyang/Documents/devops_study/ops/apps/idcs/views.py", line 40, in idc_detail
    return JSONResponse(serializer.data)
  File "/Library/Frameworks/Python.framework/Versions/3.6/lib/python3.6/site-packages/rest_framework/serializers.py", line 563, in data
    ret = super(Serializer, self).data
  File "/Library/Frameworks/Python.framework/Versions/3.6/lib/python3.6/site-packages/rest_framework/serializers.py", line 262, in data
    self._data = self.to_representation(self.instance)
  File "/Library/Frameworks/Python.framework/Versions/3.6/lib/python3.6/site-packages/rest_framework/serializers.py", line 517, in to_representation
    attribute = field.get_attribute(instance)
  File "/Library/Frameworks/Python.framework/Versions/3.6/lib/python3.6/site-packages/rest_framework/fields.py", line 474, in get_attribute
    raise type(exc)(msg)
AttributeError: Got AttributeError when attempting to get a value for field `name` on serializer `IdcSerializers`.
The serializer field might be named incorrectly and not match any attribute or key on the `QuerySet` instance.
Original exception text was: 'QuerySet' object has no attribute 'name'.
2019-03-06 23:48:19  django.request  ERROR  [135]   Internal Server Error: /idcs/1/
Traceback (most recent call last):
  File "/Library/Frameworks/Python.framework/Versions/3.6/lib/python3.6/site-packages/rest_framework/fields.py", line 453, in get_attribute
    return get_attribute(instance, self.source_attrs)
  File "/Library/Frameworks/Python.framework/Versions/3.6/lib/python3.6/site-packages/rest_framework/fields.py", line 101, in get_attribute
    instance = getattr(instance, attr)
AttributeError: 'QuerySet' object has no attribute 'name'

During handling of the above exception, another exception occurred:

Traceback (most recent call last):
  File "/Library/Frameworks/Python.framework/Versions/3.6/lib/python3.6/site-packages/django/core/handlers/exception.py", line 41, in inner
    response = get_response(request)
  File "/Library/Frameworks/Python.framework/Versions/3.6/lib/python3.6/site-packages/django/core/handlers/base.py", line 187, in _get_response
    response = self.process_exception_by_middleware(e, request)
  File "/Library/Frameworks/Python.framework/Versions/3.6/lib/python3.6/site-packages/django/core/handlers/base.py", line 185, in _get_response
    response = wrapped_callback(request, *callback_args, **callback_kwargs)
  File "/Users/yangyang/Documents/devops_study/ops/apps/idcs/views.py", line 40, in idc_detail
    return JSONResponse(serializer.data)
  File "/Library/Frameworks/Python.framework/Versions/3.6/lib/python3.6/site-packages/rest_framework/serializers.py", line 563, in data
    ret = super(Serializer, self).data
  File "/Library/Frameworks/Python.framework/Versions/3.6/lib/python3.6/site-packages/rest_framework/serializers.py", line 262, in data
    self._data = self.to_representation(self.instance)
  File "/Library/Frameworks/Python.framework/Versions/3.6/lib/python3.6/site-packages/rest_framework/serializers.py", line 517, in to_representation
    attribute = field.get_attribute(instance)
  File "/Library/Frameworks/Python.framework/Versions/3.6/lib/python3.6/site-packages/rest_framework/fields.py", line 474, in get_attribute
    raise type(exc)(msg)
AttributeError: Got AttributeError when attempting to get a value for field `name` on serializer `IdcSerializers`.
The serializer field might be named incorrectly and not match any attribute or key on the `QuerySet` instance.
Original exception text was: 'QuerySet' object has no attribute 'name'.
2019-03-06 23:48:30  django.request  ERROR  [135]   Internal Server Error: /idcs/1/
Traceback (most recent call last):
  File "/Library/Frameworks/Python.framework/Versions/3.6/lib/python3.6/site-packages/rest_framework/fields.py", line 453, in get_attribute
    return get_attribute(instance, self.source_attrs)
  File "/Library/Frameworks/Python.framework/Versions/3.6/lib/python3.6/site-packages/rest_framework/fields.py", line 101, in get_attribute
    instance = getattr(instance, attr)
AttributeError: 'QuerySet' object has no attribute 'name'

During handling of the above exception, another exception occurred:

Traceback (most recent call last):
  File "/Library/Frameworks/Python.framework/Versions/3.6/lib/python3.6/site-packages/django/core/handlers/exception.py", line 41, in inner
    response = get_response(request)
  File "/Library/Frameworks/Python.framework/Versions/3.6/lib/python3.6/site-packages/django/core/handlers/base.py", line 187, in _get_response
    response = self.process_exception_by_middleware(e, request)
  File "/Library/Frameworks/Python.framework/Versions/3.6/lib/python3.6/site-packages/django/core/handlers/base.py", line 185, in _get_response
    response = wrapped_callback(request, *callback_args, **callback_kwargs)
  File "/Users/yangyang/Documents/devops_study/ops/apps/idcs/views.py", line 40, in idc_detail
    return JSONResponse(serializer.data)
  File "/Library/Frameworks/Python.framework/Versions/3.6/lib/python3.6/site-packages/rest_framework/serializers.py", line 563, in data
    ret = super(Serializer, self).data
  File "/Library/Frameworks/Python.framework/Versions/3.6/lib/python3.6/site-packages/rest_framework/serializers.py", line 262, in data
    self._data = self.to_representation(self.instance)
  File "/Library/Frameworks/Python.framework/Versions/3.6/lib/python3.6/site-packages/rest_framework/serializers.py", line 517, in to_representation
    attribute = field.get_attribute(instance)
  File "/Library/Frameworks/Python.framework/Versions/3.6/lib/python3.6/site-packages/rest_framework/fields.py", line 474, in get_attribute
    raise type(exc)(msg)
AttributeError: Got AttributeError when attempting to get a value for field `name` on serializer `IdcSerializers`.
The serializer field might be named incorrectly and not match any attribute or key on the `QuerySet` instance.
Original exception text was: 'QuerySet' object has no attribute 'name'.
2019-03-06 23:50:29  django.request  WARNING  [152]   Not Found: /idcs/3/
2019-03-06 23:50:41  django.request  WARNING  [152]   Not Found: /idcs/3/
2019-03-06 23:50:43  django.request  WARNING  [152]   Not Found: /idcs/3/
>>>>>>> 28de3e67c806bd548f32ba1fec70e7e0ab4fa46f
