2019-03-06 22:49:33  django.template  DEBUG  [925]   Exception while resolving variable 'name' in template 'unknown'.
Traceback (most recent call last):
  File "/Library/Frameworks/Python.framework/Versions/3.6/lib/python3.6/site-packages/django/core/handlers/exception.py", line 41, in inner
    response = get_response(request)
  File "/Library/Frameworks/Python.framework/Versions/3.6/lib/python3.6/site-packages/django/core/handlers/base.py", line 172, in _get_response
    resolver_match = resolver.resolve(request.path_info)
  File "/Library/Frameworks/Python.framework/Versions/3.6/lib/python3.6/site-packages/django/urls/resolvers.py", line 394, in resolve
    raise Resolver404({'tried': tried, 'path': new_path})
django.urls.exceptions.Resolver404: {'tried': [[<RegexURLResolver <RegexURLPattern list> (admin:admin) ^admin/>], [<RegexURLResolver <module 'idcs.urls' from '/Users/yangyang/Documents/devops_study/ops/apps/idcs/urls.py'> (None:None) ^>, <RegexURLPattern idc_list idcs/>]], 'path': 'stark/asset/fixphone/list'}

During handling of the above exception, another exception occurred:

Traceback (most recent call last):
  File "/Library/Frameworks/Python.framework/Versions/3.6/lib/python3.6/site-packages/django/template/base.py", line 882, in _resolve_lookup
    current = current[bit]
TypeError: 'RegexURLResolver' object is not subscriptable

During handling of the above exception, another exception occurred:

Traceback (most recent call last):
  File "/Library/Frameworks/Python.framework/Versions/3.6/lib/python3.6/site-packages/django/template/base.py", line 890, in _resolve_lookup
    current = getattr(current, bit)
AttributeError: 'RegexURLResolver' object has no attribute 'name'

During handling of the above exception, another exception occurred:

Traceback (most recent call last):
  File "/Library/Frameworks/Python.framework/Versions/3.6/lib/python3.6/site-packages/django/template/base.py", line 896, in _resolve_lookup
    current = current[int(bit)]
ValueError: invalid literal for int() with base 10: 'name'

During handling of the above exception, another exception occurred:

Traceback (most recent call last):
  File "/Library/Frameworks/Python.framework/Versions/3.6/lib/python3.6/site-packages/django/template/base.py", line 903, in _resolve_lookup
    (bit, current))  # missing attribute
django.template.base.VariableDoesNotExist: Failed lookup for key [name] in '<RegexURLResolver <RegexURLPattern list> (admin:admin) ^admin/>'
2019-03-06 22:49:33  django.request  WARNING  [152]   Not Found: /stark/asset/fixphone/list
2019-03-06 22:49:33  django.server  WARNING  [124]   "GET /stark/asset/fixphone/list HTTP/1.1" 404 2171
2019-03-06 22:50:01  django.server  INFO  [124]   "GET /idcs HTTP/1.1" 301 0
2019-03-06 22:50:02  django.server  INFO  [124]   "GET /idcs/ HTTP/1.1" 200 373
2019-03-06 22:50:02  django.template  DEBUG  [925]   Exception while resolving variable 'name' in template 'unknown'.
Traceback (most recent call last):
  File "/Library/Frameworks/Python.framework/Versions/3.6/lib/python3.6/site-packages/django/core/handlers/exception.py", line 41, in inner
    response = get_response(request)
  File "/Library/Frameworks/Python.framework/Versions/3.6/lib/python3.6/site-packages/django/core/handlers/base.py", line 172, in _get_response
    resolver_match = resolver.resolve(request.path_info)
  File "/Library/Frameworks/Python.framework/Versions/3.6/lib/python3.6/site-packages/django/urls/resolvers.py", line 394, in resolve
    raise Resolver404({'tried': tried, 'path': new_path})
django.urls.exceptions.Resolver404: {'tried': [[<RegexURLResolver <RegexURLPattern list> (admin:admin) ^admin/>], [<RegexURLResolver <module 'idcs.urls' from '/Users/yangyang/Documents/devops_study/ops/apps/idcs/urls.py'> (None:None) ^>, <RegexURLPattern idc_list idcs/>]], 'path': 'favicon.ico'}

During handling of the above exception, another exception occurred:

Traceback (most recent call last):
  File "/Library/Frameworks/Python.framework/Versions/3.6/lib/python3.6/site-packages/django/template/base.py", line 882, in _resolve_lookup
    current = current[bit]
TypeError: 'RegexURLResolver' object is not subscriptable

During handling of the above exception, another exception occurred:

Traceback (most recent call last):
  File "/Library/Frameworks/Python.framework/Versions/3.6/lib/python3.6/site-packages/django/template/base.py", line 890, in _resolve_lookup
    current = getattr(current, bit)
AttributeError: 'RegexURLResolver' object has no attribute 'name'

During handling of the above exception, another exception occurred:

Traceback (most recent call last):
  File "/Library/Frameworks/Python.framework/Versions/3.6/lib/python3.6/site-packages/django/template/base.py", line 896, in _resolve_lookup
    current = current[int(bit)]
ValueError: invalid literal for int() with base 10: 'name'

During handling of the above exception, another exception occurred:

Traceback (most recent call last):
  File "/Library/Frameworks/Python.framework/Versions/3.6/lib/python3.6/site-packages/django/template/base.py", line 903, in _resolve_lookup
    (bit, current))  # missing attribute
django.template.base.VariableDoesNotExist: Failed lookup for key [name] in '<RegexURLResolver <RegexURLPattern list> (admin:admin) ^admin/>'
2019-03-06 22:50:02  django.request  WARNING  [152]   Not Found: /favicon.ico
2019-03-06 22:50:02  django.server  WARNING  [124]   "GET /favicon.ico HTTP/1.1" 404 2129
2019-03-06 22:50:36  django.server  INFO  [124]   "GET /idcs/ HTTP/1.1" 200 373
2019-03-06 22:50:38  django.server  INFO  [124]   "GET /idcs/ HTTP/1.1" 200 373
2019-03-06 22:52:04  django.server  INFO  [124]   "GET /idcs/ HTTP/1.1" 200 373
2019-03-06 22:55:03  urllib3.connectionpool  DEBUG  [205]   Starting new HTTP connection (1): 127.0.0.1:8000
2019-03-06 22:55:03  django.security.csrf  WARNING  [160]   Forbidden (CSRF cookie not set.): /idcs/
2019-03-06 22:55:03  django.server  WARNING  [124]   "POST /idcs/ HTTP/1.1" 403 2857
2019-03-06 22:55:03  urllib3.connectionpool  DEBUG  [393]   http://127.0.0.1:8000 "POST /idcs/ HTTP/1.1" 403 2857
2019-03-06 22:56:06  urllib3.connectionpool  DEBUG  [205]   Starting new HTTP connection (1): 127.0.0.1:8000
2019-03-06 22:56:06  django.security.csrf  WARNING  [160]   Forbidden (CSRF cookie not set.): /idcs/
2019-03-06 22:56:06  django.server  WARNING  [124]   "POST /idcs/ HTTP/1.1" 403 2857
2019-03-06 22:56:06  urllib3.connectionpool  DEBUG  [393]   http://127.0.0.1:8000 "POST /idcs/ HTTP/1.1" 403 2857
2019-03-06 22:56:11  urllib3.connectionpool  DEBUG  [205]   Starting new HTTP connection (1): 127.0.0.1:8000
2019-03-06 22:56:11  django.request  ERROR  [135]   Internal Server Error: /idcs/
Traceback (most recent call last):
  File "/Library/Frameworks/Python.framework/Versions/3.6/lib/python3.6/site-packages/django/core/handlers/exception.py", line 41, in inner
    response = get_response(request)
  File "/Library/Frameworks/Python.framework/Versions/3.6/lib/python3.6/site-packages/django/core/handlers/base.py", line 187, in _get_response
    response = self.process_exception_by_middleware(e, request)
  File "/Library/Frameworks/Python.framework/Versions/3.6/lib/python3.6/site-packages/django/core/handlers/base.py", line 185, in _get_response
    response = wrapped_callback(request, *callback_args, **callback_kwargs)
  File "/Users/yangyang/Documents/devops_study/ops/apps/idcs/views.py", line 20, in idc_list
    data = JSONParser.parse(request)
TypeError: parse() missing 1 required positional argument: 'stream'
2019-03-06 22:56:11  django.server  ERROR  [124]   "POST /idcs/ HTTP/1.1" 500 65233
2019-03-06 22:56:11  urllib3.connectionpool  DEBUG  [393]   http://127.0.0.1:8000 "POST /idcs/ HTTP/1.1" 500 65233
2019-03-06 23:03:29  django.request  ERROR  [135]   Internal Server Error: /idcs
Traceback (most recent call last):
  File "/Library/Frameworks/Python.framework/Versions/3.6/lib/python3.6/site-packages/django/core/handlers/exception.py", line 41, in inner
    response = get_response(request)
  File "/Library/Frameworks/Python.framework/Versions/3.6/lib/python3.6/site-packages/django/utils/deprecation.py", line 138, in __call__
    response = self.process_request(request)
  File "/Library/Frameworks/Python.framework/Versions/3.6/lib/python3.6/site-packages/django/middleware/common.py", line 64, in process_request
    path = self.get_full_path_with_slash(request)
  File "/Library/Frameworks/Python.framework/Versions/3.6/lib/python3.6/site-packages/django/middleware/common.py", line 104, in get_full_path_with_slash
    'url': request.get_host() + new_path,
RuntimeError: You called this URL via POST, but the URL doesn't end in a slash and you have APPEND_SLASH set. Django can't redirect to the slash URL while maintaining POST data. Change your form to point to 127.0.0.1:8000/idcs/ (note the trailing slash), or set APPEND_SLASH=False in your Django settings.
2019-03-06 23:03:29  django.server  ERROR  [124]   "POST /idcs HTTP/1.1" 500 64471
2019-03-06 23:03:51  django.request  ERROR  [135]   Internal Server Error: /idcs
Traceback (most recent call last):
  File "/Library/Frameworks/Python.framework/Versions/3.6/lib/python3.6/site-packages/django/core/handlers/exception.py", line 41, in inner
    response = get_response(request)
  File "/Library/Frameworks/Python.framework/Versions/3.6/lib/python3.6/site-packages/django/utils/deprecation.py", line 138, in __call__
    response = self.process_request(request)
  File "/Library/Frameworks/Python.framework/Versions/3.6/lib/python3.6/site-packages/django/middleware/common.py", line 64, in process_request
    path = self.get_full_path_with_slash(request)
  File "/Library/Frameworks/Python.framework/Versions/3.6/lib/python3.6/site-packages/django/middleware/common.py", line 104, in get_full_path_with_slash
    'url': request.get_host() + new_path,
RuntimeError: You called this URL via POST, but the URL doesn't end in a slash and you have APPEND_SLASH set. Django can't redirect to the slash URL while maintaining POST data. Change your form to point to 127.0.0.1:8000/idcs/ (note the trailing slash), or set APPEND_SLASH=False in your Django settings.
2019-03-06 23:03:51  django.server  ERROR  [124]   "POST /idcs HTTP/1.1" 500 63969
2019-03-06 23:04:19  django.request  ERROR  [135]   Internal Server Error: /idcs/
Traceback (most recent call last):
  File "/Library/Frameworks/Python.framework/Versions/3.6/lib/python3.6/site-packages/django/core/handlers/exception.py", line 41, in inner
    response = get_response(request)
  File "/Library/Frameworks/Python.framework/Versions/3.6/lib/python3.6/site-packages/django/core/handlers/base.py", line 187, in _get_response
    response = self.process_exception_by_middleware(e, request)
  File "/Library/Frameworks/Python.framework/Versions/3.6/lib/python3.6/site-packages/django/core/handlers/base.py", line 185, in _get_response
    response = wrapped_callback(request, *callback_args, **callback_kwargs)
  File "/Users/yangyang/Documents/devops_study/ops/apps/idcs/views.py", line 20, in idc_list
    data = JSONParser.parse(request)
TypeError: parse() missing 1 required positional argument: 'stream'
2019-03-06 23:04:19  django.server  ERROR  [124]   "POST /idcs/ HTTP/1.1" 500 64677
2019-03-06 23:07:38  django.request  ERROR  [135]   Internal Server Error: /idcs/
Traceback (most recent call last):
  File "/Library/Frameworks/Python.framework/Versions/3.6/lib/python3.6/site-packages/django/core/handlers/exception.py", line 41, in inner
    response = get_response(request)
  File "/Library/Frameworks/Python.framework/Versions/3.6/lib/python3.6/site-packages/django/core/handlers/base.py", line 187, in _get_response
    response = self.process_exception_by_middleware(e, request)
  File "/Library/Frameworks/Python.framework/Versions/3.6/lib/python3.6/site-packages/django/core/handlers/base.py", line 185, in _get_response
    response = wrapped_callback(request, *callback_args, **callback_kwargs)
  File "/Users/yangyang/Documents/devops_study/ops/apps/idcs/views.py", line 20, in idc_list
    data = JSONParser.parse(request)
TypeError: parse() missing 1 required positional argument: 'stream'
2019-03-06 23:07:38  django.server  ERROR  [124]   "POST /idcs/ HTTP/1.1" 500 64677
2019-03-06 23:08:29  django.request  ERROR  [135]   Internal Server Error: /idcs/
Traceback (most recent call last):
  File "/Library/Frameworks/Python.framework/Versions/3.6/lib/python3.6/site-packages/django/core/handlers/exception.py", line 41, in inner
    response = get_response(request)
  File "/Library/Frameworks/Python.framework/Versions/3.6/lib/python3.6/site-packages/django/core/handlers/base.py", line 187, in _get_response
    response = self.process_exception_by_middleware(e, request)
  File "/Library/Frameworks/Python.framework/Versions/3.6/lib/python3.6/site-packages/django/core/handlers/base.py", line 185, in _get_response
    response = wrapped_callback(request, *callback_args, **callback_kwargs)
  File "/Users/yangyang/Documents/devops_study/ops/apps/idcs/views.py", line 20, in idc_list
    data = JSONParser.parse(request)
TypeError: parse() missing 1 required positional argument: 'stream'
2019-03-06 23:08:29  django.server  ERROR  [124]   "POST /idcs/ HTTP/1.1" 500 64677
2019-03-06 23:09:56  django.server  INFO  [124]   "POST /idcs/ HTTP/1.1" 200 0
2019-03-06 23:11:23  django.server  INFO  [124]   "POST /idcs/ HTTP/1.1" 200 9
2019-03-06 23:18:13  django.server  INFO  [124]   "POST /idcs/ HTTP/1.1" 200 9
2019-03-06 23:20:35  django.server  INFO  [124]   "POST /idcs/ HTTP/1.1" 200 121
2019-03-06 23:26:25  django.request  ERROR  [135]   Internal Server Error: /idcs/
Traceback (most recent call last):
  File "/Library/Frameworks/Python.framework/Versions/3.6/lib/python3.6/site-packages/django/core/handlers/exception.py", line 41, in inner
    response = get_response(request)
  File "/Library/Frameworks/Python.framework/Versions/3.6/lib/python3.6/site-packages/django/core/handlers/base.py", line 187, in _get_response
    response = self.process_exception_by_middleware(e, request)
  File "/Library/Frameworks/Python.framework/Versions/3.6/lib/python3.6/site-packages/django/core/handlers/base.py", line 185, in _get_response
    response = wrapped_callback(request, *callback_args, **callback_kwargs)
  File "/Users/yangyang/Documents/devops_study/ops/apps/idcs/views.py", line 25, in idc_list
    return  JSONResponse(serializer.data)
  File "/Users/yangyang/Documents/devops_study/ops/apps/idcs/views.py", line 16, in __init__
    super(JSONRenderer,self).__init__(data=content, **kwargs)
TypeError: super(type, obj): obj must be an instance or subtype of type
2019-03-06 23:26:25  django.server  ERROR  [124]   "GET /idcs/ HTTP/1.1" 500 73659
2019-03-06 23:26:41  django.request  ERROR  [135]   Internal Server Error: /idcs/
Traceback (most recent call last):
  File "/Library/Frameworks/Python.framework/Versions/3.6/lib/python3.6/site-packages/django/core/handlers/exception.py", line 41, in inner
    response = get_response(request)
  File "/Library/Frameworks/Python.framework/Versions/3.6/lib/python3.6/site-packages/django/core/handlers/base.py", line 187, in _get_response
    response = self.process_exception_by_middleware(e, request)
  File "/Library/Frameworks/Python.framework/Versions/3.6/lib/python3.6/site-packages/django/core/handlers/base.py", line 185, in _get_response
    response = wrapped_callback(request, *callback_args, **callback_kwargs)
  File "/Users/yangyang/Documents/devops_study/ops/apps/idcs/views.py", line 25, in idc_list
    return  JSONResponse(serializer.data)
  File "/Users/yangyang/Documents/devops_study/ops/apps/idcs/views.py", line 16, in __init__
    super(JSONRenderer,self).__init__(content=content, **kwargs)
TypeError: super(type, obj): obj must be an instance or subtype of type
2019-03-06 23:26:41  django.server  ERROR  [124]   "GET /idcs/ HTTP/1.1" 500 73665
2019-03-06 23:29:04  django.request  ERROR  [135]   Internal Server Error: /idcs/
Traceback (most recent call last):
  File "/Library/Frameworks/Python.framework/Versions/3.6/lib/python3.6/site-packages/django/core/handlers/exception.py", line 41, in inner
    response = get_response(request)
  File "/Library/Frameworks/Python.framework/Versions/3.6/lib/python3.6/site-packages/django/core/handlers/base.py", line 187, in _get_response
    response = self.process_exception_by_middleware(e, request)
  File "/Library/Frameworks/Python.framework/Versions/3.6/lib/python3.6/site-packages/django/core/handlers/base.py", line 185, in _get_response
    response = wrapped_callback(request, *callback_args, **callback_kwargs)
  File "/Users/yangyang/Documents/devops_study/ops/apps/idcs/views.py", line 25, in idc_list
    return  JSONResponse(serializer.data)
  File "/Users/yangyang/Documents/devops_study/ops/apps/idcs/views.py", line 16, in __init__
    super(JSONRenderer,self).__init__(content=content, **kwargs)
TypeError: super(type, obj): obj must be an instance or subtype of type
2019-03-06 23:29:04  django.server  ERROR  [124]   "GET /idcs/ HTTP/1.1" 500 74739
2019-03-06 23:32:11  django.server  INFO  [124]   "GET /idcs/ HTTP/1.1" 200 739
2019-03-06 23:47:41  django.server  INFO  [124]   "GET /idcs/1 HTTP/1.1" 301 0
2019-03-06 23:47:41  django.request  ERROR  [135]   Internal Server Error: /idcs/1/
Traceback (most recent call last):
  File "/Library/Frameworks/Python.framework/Versions/3.6/lib/python3.6/site-packages/rest_framework/fields.py", line 453, in get_attribute
    return get_attribute(instance, self.source_attrs)
  File "/Library/Frameworks/Python.framework/Versions/3.6/lib/python3.6/site-packages/rest_framework/fields.py", line 101, in get_attribute
    instance = getattr(instance, attr)
AttributeError: 'QuerySet' object has no attribute 'name'

During handling of the above exception, another exception occurred:

Traceback (most recent call last):
  File "/Library/Frameworks/Python.framework/Versions/3.6/lib/python3.6/site-packages/django/core/handlers/exception.py", line 41, in inner
    response = get_response(request)
  File "/Library/Frameworks/Python.framework/Versions/3.6/lib/python3.6/site-packages/django/core/handlers/base.py", line 187, in _get_response
    response = self.process_exception_by_middleware(e, request)
  File "/Library/Frameworks/Python.framework/Versions/3.6/lib/python3.6/site-packages/django/core/handlers/base.py", line 185, in _get_response
    response = wrapped_callback(request, *callback_args, **callback_kwargs)
  File "/Users/yangyang/Documents/devops_study/ops/apps/idcs/views.py", line 40, in idc_detail
    return JSONResponse(serializer.data)
  File "/Library/Frameworks/Python.framework/Versions/3.6/lib/python3.6/site-packages/rest_framework/serializers.py", line 563, in data
    ret = super(Serializer, self).data
  File "/Library/Frameworks/Python.framework/Versions/3.6/lib/python3.6/site-packages/rest_framework/serializers.py", line 262, in data
    self._data = self.to_representation(self.instance)
  File "/Library/Frameworks/Python.framework/Versions/3.6/lib/python3.6/site-packages/rest_framework/serializers.py", line 517, in to_representation
    attribute = field.get_attribute(instance)
  File "/Library/Frameworks/Python.framework/Versions/3.6/lib/python3.6/site-packages/rest_framework/fields.py", line 474, in get_attribute
    raise type(exc)(msg)
AttributeError: Got AttributeError when attempting to get a value for field `name` on serializer `IdcSerializers`.
The serializer field might be named incorrectly and not match any attribute or key on the `QuerySet` instance.
Original exception text was: 'QuerySet' object has no attribute 'name'.
2019-03-06 23:47:42  django.server  ERROR  [124]   "GET /idcs/1/ HTTP/1.1" 500 92468
2019-03-06 23:48:19  django.request  ERROR  [135]   Internal Server Error: /idcs/1/
Traceback (most recent call last):
  File "/Library/Frameworks/Python.framework/Versions/3.6/lib/python3.6/site-packages/rest_framework/fields.py", line 453, in get_attribute
    return get_attribute(instance, self.source_attrs)
  File "/Library/Frameworks/Python.framework/Versions/3.6/lib/python3.6/site-packages/rest_framework/fields.py", line 101, in get_attribute
    instance = getattr(instance, attr)
AttributeError: 'QuerySet' object has no attribute 'name'

During handling of the above exception, another exception occurred:

Traceback (most recent call last):
  File "/Library/Frameworks/Python.framework/Versions/3.6/lib/python3.6/site-packages/django/core/handlers/exception.py", line 41, in inner
    response = get_response(request)
  File "/Library/Frameworks/Python.framework/Versions/3.6/lib/python3.6/site-packages/django/core/handlers/base.py", line 187, in _get_response
    response = self.process_exception_by_middleware(e, request)
  File "/Library/Frameworks/Python.framework/Versions/3.6/lib/python3.6/site-packages/django/core/handlers/base.py", line 185, in _get_response
    response = wrapped_callback(request, *callback_args, **callback_kwargs)
  File "/Users/yangyang/Documents/devops_study/ops/apps/idcs/views.py", line 40, in idc_detail
    return JSONResponse(serializer.data)
  File "/Library/Frameworks/Python.framework/Versions/3.6/lib/python3.6/site-packages/rest_framework/serializers.py", line 563, in data
    ret = super(Serializer, self).data
  File "/Library/Frameworks/Python.framework/Versions/3.6/lib/python3.6/site-packages/rest_framework/serializers.py", line 262, in data
    self._data = self.to_representation(self.instance)
  File "/Library/Frameworks/Python.framework/Versions/3.6/lib/python3.6/site-packages/rest_framework/serializers.py", line 517, in to_representation
    attribute = field.get_attribute(instance)
  File "/Library/Frameworks/Python.framework/Versions/3.6/lib/python3.6/site-packages/rest_framework/fields.py", line 474, in get_attribute
    raise type(exc)(msg)
AttributeError: Got AttributeError when attempting to get a value for field `name` on serializer `IdcSerializers`.
The serializer field might be named incorrectly and not match any attribute or key on the `QuerySet` instance.
Original exception text was: 'QuerySet' object has no attribute 'name'.
2019-03-06 23:48:20  django.server  ERROR  [124]   "GET /idcs/1/ HTTP/1.1" 500 92326
2019-03-06 23:48:30  django.request  ERROR  [135]   Internal Server Error: /idcs/1/
Traceback (most recent call last):
  File "/Library/Frameworks/Python.framework/Versions/3.6/lib/python3.6/site-packages/rest_framework/fields.py", line 453, in get_attribute
    return get_attribute(instance, self.source_attrs)
  File "/Library/Frameworks/Python.framework/Versions/3.6/lib/python3.6/site-packages/rest_framework/fields.py", line 101, in get_attribute
    instance = getattr(instance, attr)
AttributeError: 'QuerySet' object has no attribute 'name'

During handling of the above exception, another exception occurred:

Traceback (most recent call last):
  File "/Library/Frameworks/Python.framework/Versions/3.6/lib/python3.6/site-packages/django/core/handlers/exception.py", line 41, in inner
    response = get_response(request)
  File "/Library/Frameworks/Python.framework/Versions/3.6/lib/python3.6/site-packages/django/core/handlers/base.py", line 187, in _get_response
    response = self.process_exception_by_middleware(e, request)
  File "/Library/Frameworks/Python.framework/Versions/3.6/lib/python3.6/site-packages/django/core/handlers/base.py", line 185, in _get_response
    response = wrapped_callback(request, *callback_args, **callback_kwargs)
  File "/Users/yangyang/Documents/devops_study/ops/apps/idcs/views.py", line 40, in idc_detail
    return JSONResponse(serializer.data)
  File "/Library/Frameworks/Python.framework/Versions/3.6/lib/python3.6/site-packages/rest_framework/serializers.py", line 563, in data
    ret = super(Serializer, self).data
  File "/Library/Frameworks/Python.framework/Versions/3.6/lib/python3.6/site-packages/rest_framework/serializers.py", line 262, in data
    self._data = self.to_representation(self.instance)
  File "/Library/Frameworks/Python.framework/Versions/3.6/lib/python3.6/site-packages/rest_framework/serializers.py", line 517, in to_representation
    attribute = field.get_attribute(instance)
  File "/Library/Frameworks/Python.framework/Versions/3.6/lib/python3.6/site-packages/rest_framework/fields.py", line 474, in get_attribute
    raise type(exc)(msg)
AttributeError: Got AttributeError when attempting to get a value for field `name` on serializer `IdcSerializers`.
The serializer field might be named incorrectly and not match any attribute or key on the `QuerySet` instance.
Original exception text was: 'QuerySet' object has no attribute 'name'.
2019-03-06 23:48:31  django.server  ERROR  [124]   "GET /idcs/1/ HTTP/1.1" 500 92326
2019-03-06 23:50:18  django.server  INFO  [124]   "GET /idcs/1/ HTTP/1.1" 200 121
2019-03-06 23:50:24  django.server  INFO  [124]   "GET /idcs/2/ HTTP/1.1" 200 127
2019-03-06 23:50:29  django.server  INFO  [124]   "GET /idcs/3 HTTP/1.1" 301 0
2019-03-06 23:50:29  django.request  WARNING  [152]   Not Found: /idcs/3/
2019-03-06 23:50:29  django.server  WARNING  [124]   "GET /idcs/3/ HTTP/1.1" 404 0
2019-03-06 23:50:41  django.request  WARNING  [152]   Not Found: /idcs/3/
2019-03-06 23:50:41  django.server  WARNING  [124]   "GET /idcs/3/ HTTP/1.1" 404 0
2019-03-06 23:50:43  django.request  WARNING  [152]   Not Found: /idcs/3/
2019-03-06 23:50:43  django.server  WARNING  [124]   "GET /idcs/3/ HTTP/1.1" 404 0
2019-03-06 23:50:49  django.server  INFO  [124]   "GET /idcs/4/ HTTP/1.1" 200 121
2019-03-06 23:52:14  django.server  INFO  [124]   "GET /idcs/1/ HTTP/1.1" 200 121
2019-03-06 23:52:54  django.server  INFO  [124]   "PUT /idcs/1/ HTTP/1.1" 200 115
2019-03-06 23:53:17  django.server  INFO  [124]   "GET /idcs/1/ HTTP/1.1" 200 115
2019-03-06 23:54:25  django.server  INFO  [124]   "GET /idcs/1/ HTTP/1.1" 200 115
2019-03-06 23:54:26  django.server  INFO  [124]   "GET /idcs/1/ HTTP/1.1" 200 115
2019-03-06 23:54:27  django.server  INFO  [124]   "GET /idcs/1/ HTTP/1.1" 200 115
2019-03-06 23:54:35  django.server  INFO  [124]   "PUT /idcs/1/ HTTP/1.1" 200 115
2019-03-06 23:57:02  django.server  INFO  [124]   "PUT /idcs/1/ HTTP/1.1" 200 115
2019-03-06 23:57:04  django.server  INFO  [124]   "PUT /idcs/1/ HTTP/1.1" 200 115
2019-03-06 23:57:06  django.server  INFO  [124]   "PUT /idcs/1/ HTTP/1.1" 200 115
2019-03-06 23:57:07  django.server  INFO  [124]   "PUT /idcs/1/ HTTP/1.1" 200 115
2019-03-06 23:57:08  django.server  INFO  [124]   "PUT /idcs/1/ HTTP/1.1" 200 115
2019-03-06 23:57:09  django.server  INFO  [124]   "PUT /idcs/1/ HTTP/1.1" 200 115
